Workbook
Name AREA: #REF!
Name GST: #REF!
Name IDP: #REF!
Name IFT: #REF!
Name PLG: #REF!

Sheet Resumen  - Se oculta 2,0
B5: IFT | C5: =+IFT!O3 -> 0.25 | D5: =+IFT!C8 -> EMPLAZAMIENTO | F5: =+IFT!F8 -> 0.94 | H5: =+IFT!F3 -> 0.93175 | I5: =+'Dashboard Gral (2.0)'!C5 -> 0.25
D6: =+IFT!C19 -> EDIFICACION | F6: =+IFT!F19 -> 0.925 | J6: =+H5*I5+H10*I10+H16*I16+H21*I21 -> 0.95677083 | L6: COM. ALDO PATRICIO BALKENHOL FLORES EIRL
D7: =+IFT!C40 -> ALMACENAMIENTO Y MANIPULEO | F7: =+IFT!F40 -> 0.91 | J7: =+ROUND(J6*100,1)&"%"&" "&D39 -> 95,7% PROACTIVO
D8: =+IFT!C58 -> TRANSPORTE Y REPARTO | F8: =+IFT!F58 -> 1 | J8: Valor Año anterior | L8: =VLOOKUP(L6,[3]Gantt!$E$3:$AG$31,29,0) -> 0.9683
D9: =+IFT!C61 -> INFORMACIÓN Y COMUNICACIONES | F9: =+IFT!F61 -> 1 | L9: =IFERROR(IF(ROUND((J6-L8)*100,1)<0,"-"&ROUND((J6-L8)*100,1)&" pp vs AA","+"&ROUND((J6-L8)*100,1)&" pp vs AA"),"N/A") -> --1,2 pp vs AA
B10: PLG | C10: =+PLG!O3 -> 0.25 | D10: =+PLG!C8 -> ABASTECIMIENTO Y RECEPCIÓN | F10: =+PLG!F8 -> 1 | H10: =+PLG!F3 -> 0.96 | I10: =+'Dashboard Gral (2.0)'!C10 -> 0.25
D11: =+PLG!C18 -> ALMACENAMIENTO Y MANIPULEO | F11: =+PLG!F18 -> 0.75
D12: =+PLG!C28 -> REPOSICION INVENTARIOS | F12: =+PLG!F28 -> 1
D13: =+PLG!C36 -> CONSOLIDADOS Y PEDIDOS | F13: =+PLG!F36 -> 1
D14: =+PLG!C48 -> TRANSPORTE Y REPARTO | F14: =+PLG!F48 -> 0.85
D15: =+PLG!C56 -> RETORNO Y/O DEVOLUCIONES | F15: =+PLG!F56 -> 1
B16: GST | C16: =+GST!O3 -> 0.2 | D16: =+GST!C8 -> ORGANIZACIÓN | F16: =+GST!F8 -> 1 | H16: =+GST!F3 -> 0.958 | I16: =+'Dashboard Gral (2.0)'!C16 -> 0.2
D17: =+GST!C31 -> PLANIFICACION | F17: =+GST!F31 -> 1
D18: =+GST!C42 -> INFORMACION Y COMUNICACIONES | F18: =+GST!F42 -> 1
D19: =+GST!C48 -> FORMACION Y DESARROLLO | F19: =+GST!F48 -> 1
D20: =+GST!C52 -> MEDICION Y MEJORA | F20: =+GST!F52 -> 0.86
B21: IDP | C21: =+IDP!O3 -> 0.3 | D21: =+IDP!C8 -> ABASTECIMIENTO Y RECEPCIÓN | F21: =+IDP!F8 -> 1 | H21: =+IDP!F3 -> 0.97411111 | I21: =+'Dashboard Gral (2.0)'!C21 -> 0.3
D22: =+IDP!C14 -> ALMACENAMIENTO Y MANIPULEO | F22: =+IDP!F14 -> 0.94444444
D23: =+IDP!C33 -> TRANSPORTE Y REPARTO | F23: =+IDP!F33 -> 1
D24: =+IDP!C42 -> RETORNO Y/O DEVOLUCIONES | F24: =+IDP!F42 -> 1
D25: =+IDP!C49 -> LIMPIEZA | F25: =+IDP!F49 -> 1
D26: =+IDP!C58 -> MANEJO INTEGRADO DE PLAGAS | F26: =+IDP!F58 -> 0.88
B31: Categoria
B32: 85% > y 100% | D32: PROACTIVO | F32: =+D33 -> ACTIVO | G32: 0.85
B33: 70% > y < 85% | D33: ACTIVO | F33: =+D34 -> REACTIVO | G33: =+G32 -> 0.85 | H33: 0.7
B34: 50% > y < 70% | D34: REACTIVO | F34: =+D35 -> INACTIVO | G34: =+H33 -> 0.7 | H34: 0.5
B35: 25% > y < 50% | D35: INACTIVO | F35: =+D35 -> INACTIVO | G35: =+H34 -> 0.5 | H35: 0
B36: 0% > y < 25% | D36: N/A | G36: =+H35 -> 0 | H36: 0
A39: Adherencia | B39: =+J6 -> 0.95677083 | D39: =IF(B39>=G32,D32,IF(AND((B39<G33),(B39>=H33)),D33,IF(AND((B39<G34),(B39>=H34)),D34,D35))) -> PROACTIVO
R40: Estadio | S40: Indice | U40: Condicionales
A41: Condicionales | B41: =+'Condicionales 2.0'!G19 -> 12 | D41: =+ROUND(B39*100,1)&"%"&" "&D39 -> 95,7% PROACTIVO | R41: Proactivo | S41: Mayor / Igual | T41: 8.51 | U41: 12 | V41: =
A42: Categoria Final | B42: =VLOOKUP($D$39&$B$41,$K$48:$L$96,2,0) -> PROACTIVO
B43: =IF(D39=B42,"Mantiene Estadio","Cae de Estadio") -> Mantiene Estadio | D43: =+"Estadio final 2025: "&B42 -> Estadio final 2025: PROACTIVO | R43: Activo | S43: Mayor / Igual | T43: 8.51 | U43: 9 | V43: =+S43 -> Mayor / Igual
R44: Activo | S44: Mayor / Igual | T44: 7.01 | U44: 11 | V44: =+S44 -> Mayor / Igual
R46: Reactivo | S46: Mayor / Igual | T46: 8.51 | U46: 6 | V46: =+S46 -> Mayor / Igual
R47: Reactivo | S47: Mayor / Igual | T47: 7.01 | U47: 9 | V47: =+S47 -> Mayor / Igual
I48: Proactivo | J48: 12 | K48: =+I48&J48 -> Proactivo12 | L48: PROACTIVO
I49: Proactivo | J49: 11 | K49: =+I49&J49 -> Proactivo11 | L49: ACTIVO | R49: Inactivo | S49: Mayor / Igual | T49: 8.51 | U49: 6 | V49: Menor
I50: Proactivo | J50: 10 | K50: =+I50&J50 -> Proactivo10 | L50: ACTIVO | R50: Inactivo | S50: Mayor / Igual | T50: 7.01 | U50: 9 | V50: Menor
I51: Proactivo | J51: 9 | K51: =+I51&J51 -> Proactivo9 | L51: ACTIVO | R51: Inactivo | S51: Mayor / Igual | T51: 5.01 | U51: 12 | V51: Menor
...

Sheet Inicio

Sheet 2.0>>>

Sheet Dashboard Gral (2.0)
B5: IFT | C5: 0.25 | D5: =+IFT!C8 -> EMPLAZAMIENTO | G5: =+IFT!F8 -> 0.94 | I5: =+IFT!F3 -> 0.93175 | J5: =+I5*C5 -> 0.2329375
D6: =+IFT!C19 -> EDIFICACION | G6: =+IFT!F19 -> 0.925
D7: =+IFT!C40 -> ALMACENAMIENTO Y MANIPULEO | G7: =+IFT!F40 -> 0.91
D8: =+IFT!C58 -> TRANSPORTE Y REPARTO | G8: =+IFT!F58 -> 1
D9: =+IFT!C61 -> INFORMACIÓN Y COMUNICACIONES | G9: =+IFT!F61 -> 1
B10: PLG | C10: 0.25 | D10: =+PLG!C8 -> ABASTECIMIENTO Y RECEPCIÓN | G10: =+PLG!F8 -> 1 | I10: =+PLG!F3 -> 0.96 | J10: =+I10*C10 -> 0.24
D11: =+PLG!C18 -> ALMACENAMIENTO Y MANIPULEO | G11: =+PLG!F18 -> 0.75
D12: =+PLG!C28 -> REPOSICION INVENTARIOS | G12: =+PLG!F28 -> 1
D13: =+PLG!C36 -> CONSOLIDADOS Y PEDIDOS | G13: =+PLG!F36 -> 1
D14: =+PLG!C48 -> TRANSPORTE Y REPARTO | G14: =+PLG!F48 -> 0.85
D15: =+PLG!C56 -> RETORNO Y/O DEVOLUCIONES | G15: =+PLG!F56 -> 1
B16: GST | C16: 0.2 | D16: =+GST!C8 -> ORGANIZACIÓN | G16: =+GST!F8 -> 1 | I16: =+GST!F3 -> 0.958 | J16: =+I16*C16 -> 0.1916
D17: =+GST!C31 -> PLANIFICACION | G17: =+GST!F31 -> 1
D18: =+GST!C42 -> INFORMACION Y COMUNICACIONES | G18: =+GST!F42 -> 1
D19: =+GST!C48 -> FORMACION Y DESARROLLO | G19: =+GST!F48 -> 1
D20: =+GST!C52 -> MEDICION Y MEJORA | G20: =+GST!F52 -> 0.86
B21: IDP | C21: 0.3 | D21: =+IDP!C8 -> ABASTECIMIENTO Y RECEPCIÓN | G21: =+IDP!F8 -> 1 | I21: =+IDP!F3 -> 0.97411111 | J21: =+I21*C21 -> 0.29223333
D22: =+IDP!C14 -> ALMACENAMIENTO Y MANIPULEO | G22: =+IDP!F14 -> 0.94444444
D23: =+IDP!C33 -> TRANSPORTE Y REPARTO | G23: =+IDP!F33 -> 1
D24: =+IDP!C42 -> RETORNO Y/O DEVOLUCIONES | G24: =+IDP!F42 -> 1
D25: =+IDP!C49 -> LIMPIEZA | G25: =+IDP!F49 -> 1
D26: =+IDP!C58 -> MANEJO INTEGRADO DE PLAGAS | G26: =+IDP!F58 -> 0.88
D31: 85 % >= Proactivo <= 100 %
D32: 70 % >= Activo < 85 %
D33: 50 % >= Reactivo < 70 %
D34: 0 % >= Inactivo < 50 %

Sheet Condicionales 2.0
B2: # Critico | C2: # Critico | D2: Descripción | F2: # componentes Criticas | L2: Evaluación del cumplimiento
F3: Totales | G3: OK
B5: 1 | C5: CRITICO 1 | D5: =+IFT!C13 -> ENTORNO - ACCESO | F5: =COUNTIF(IFT!H:H,'Condicionales 2.0'!C5) -> 1 | G5: =SUMIF(IFT!H:H,'Condicionales 2.0'!C5,IFT!F:F) -> 1 | H5: =+G5/F5 -> 1 | I5: =+H5 -> 1 | L5: Categoria : Tolerancia sobre el total BPLs
B6: =+B5+1 -> 2 | C6: CRITICO 2 | D6: =+IFT!C22 -> LAY OUT - CAPACIDAD Y MODULACION | F6: =COUNTIF(IFT!H:H,'Condicionales 2.0'!C6) -> 1 | G6: =SUMIF(IFT!H:H,'Condicionales 2.0'!C6,IFT!F:F) -> 1 | H6: =+G6/F6 -> 1 | I6: =+H6 -> 1 | L6: % Adherencia | M6: =+'Resumen - Se oculta 2,0'!B39 -> 0.95677083 | P6: =+"BPLs Críticas Cumplidas "&M10&" de "&M9 -> BPLs Críticas Cumplidas 12 de 12
B7: =+B6+1 -> 3 | C7: CRITICO 3 | D7: =+IFT!C41 -> EPPS Y EXTINGUIDORES | F7: =COUNTIF(IFT!H:H,'Condicionales 2.0'!C7) -> 2 | G7: =SUMIF(IFT!H:H,'Condicionales 2.0'!C7,IFT!F:F) -> 2 | H7: =+G7/F7 -> 1 | I7: =+H7 -> 1 | L7: Categoria | M7: =+'Resumen - Se oculta 2,0'!D39 -> PROACTIVO
B8: =+B7+1 -> 4 | C8: CRITICO 4 | D8: =+IFT!C54 -> EQUIPAMIENTO DE MANIPULEO | F8: =COUNTIF(IFT!H:H,'Condicionales 2.0'!C8) -> 3 | G8: =SUMIF(IFT!H:H,'Condicionales 2.0'!C8,IFT!F:F) -> 3 | H8: =+G8/F8 -> 1 | I8: =+H8 -> 1
B9: =+B8+1 -> 5 | C9: CRITICO 5 | D9: =+PLG!C13 -> COORDINACIÓN DEL ABASTECIMIENTO | F9: =COUNTIF(PLG!H:H,'Condicionales 2.0'!C9) -> 4 | G9: =SUMIF(PLG!H:H,'Condicionales 2.0'!C9,PLG!F:F) -> 4 | H9: =+G9/F9 -> 1 | I9: =+H9 -> 1 | L9: Total | M9: =+F19 -> 12
B10: =+B9+1 -> 6 | C10: CRITICO 6 | D10: =+PLG!C33 -> INVENTARIOS ROTATIVOS | F10: =COUNTIF(PLG!H:H,'Condicionales 2.0'!C10) -> 3 | G10: =SUMIF(PLG!H:H,'Condicionales 2.0'!C10,PLG!F:F) -> 3 | H10: =+G10/F10 -> 1 | I10: =+H10 -> 1 | L10: Cumplidas | M10: =+G19 -> 12
B11: 7 | C11: CRITICO 7 | D11: =+GST!C23 -> PROCESOS DOCUMENTADOS | F11: =COUNTIF(GST!H:H,'Condicionales 2.0'!C11) -> 10 | G11: =SUMIF(GST!H:H,'Condicionales 2.0'!C11,GST!F:F) -> 10 | H11: =+G11/F11 -> 1 | I11: =+H11 -> 1
B12: =+B11+1 -> 8 | C12: CRITICO 8 | D12: =+GST!C55 -> INDICADORES | F12: =COUNTIF(GST!H:H,'Condicionales 2.0'!C12) -> 6 | G12: =SUMIF(GST!H:H,'Condicionales 2.0'!C12,GST!F:F) -> 6 | H12: =+G12/F12 -> 1 | I12: =+H12 -> 1 | L12: Categoria Final (con condicionales)
B13: =+B12+1 -> 9 | C13: CRITICO 9 | D13: =+IDP!C24 -> CONTROL DE TEMPERATURAS | F13: =COUNTIF(IDP!H:H,'Condicionales 2.0'!C13) -> 2 | G13: =SUMIF(IDP!H:H,'Condicionales 2.0'!C13,IDP!F:F) -> 2 | H13: =+G13/F13 -> 1 | I13: =+H13 -> 1 | L13: =+M6 -> 0.95677083 | M13: =+'Resumen - Se oculta 2,0'!B42 -> PROACTIVO
B14: =+B13+1 -> 10 | C14: CRITICO 10 | D14: =+IDP!C43 -> RECHAZOS | F14: =COUNTIF(IDP!H:H,'Condicionales 2.0'!C14) -> 2 | G14: =SUMIF(IDP!H:H,'Condicionales 2.0'!C14,IDP!F:F) -> 2 | H14: =+G14/F14 -> 1 | I14: =+H14 -> 1
B15: =+B14+1 -> 11 | C15: CRITICO 11 | D15: =+IDP!C45 -> DEVOLUCIONES DE PRODUCTOS NO APTOS | F15: =COUNTIF(IDP!H:H,'Condicionales 2.0'!C15) -> 2 | G15: =SUMIF(IDP!H:H,'Condicionales 2.0'!C15,IDP!F:F) -> 2 | H15: =+G15/F15 -> 1 | I15: =+H15 -> 1
B16: =+B15+1 -> 12 | C16: CRITICO 12 | D16: =+IDP!C60 -> CONTROL DE PLAGAS | F16: =COUNTIF(IDP!H:H,'Condicionales 2.0'!C16) -> 5 | G16: =SUMIF(IDP!H:H,'Condicionales 2.0'!C16,IDP!F:F) -> 5 | H16: =+G16/F16 -> 1 | I16: =+H16 -> 1
D18: Total COMPONENTES | F18: =SUM(F5:F16) -> 41 | G18: =SUM(G5:G16) -> 41 | H18: =+G18/F18 -> 1
D19: Total BPLs | F19: =+B16 -> 12 | G19: =COUNTIF(H5:H16,1) -> 12 | H19: =+G19/F19 -> 1

Sheet IFT
Y1: 0
F2: EV25 | K2: AE 25 | Y2: 1
E3: =+B5 -> Area de interés : Infraestructura | F3: =+O8+O19+O40+O58+O61 -> 0.93175 | K3: =+K8*N8+K19*N19+K40*N40+K58*N58+K61*N61 -> 0.992 | N3: AREA en programa | O3: 0.25 | Y3: N/A
E4: Programa | F4: =+F3*O3 -> 0.2329375 | G4: =+F4+PLG!F4+GST!F4+IDP!F4 -> 0.95677083 | K4: =+K3*O3 -> 0.248 | L4: =+K4+PLG!K4+GST!K4+IDP!K4 -> 0.959315 | Y4: NA - 1
B5: Area de interés : Infraestructura | N5: Ponderaciones en Area | Y5: NA - 0
B6: NRO. | C6: Buena Practica Logistica | E6: Componente | F6: EV25 | G6: Declaración de Buena Practica | H6: Critico | I6: Comentarios Evaluación | K6: AE 25 | N6: comp en el atributo | O6: Peso BPL
B8: 1 | C8: EMPLAZAMIENTO | F8: =SUMPRODUCT(F9:F17,N9:N17,O9:O17) -> 0.94 | K8: =SUMPRODUCT(K9:K17,N9:N17,O9:O17) -> 1 | N8: =+[1]MATRIZ!$G$8 -> 0.225 | O8: =+F8*N8 -> 0.2115
A9: 1 | B9: 1.1 | C9: ENTORNO Y SEGURIDAD EXTERNA | D9: 1.1.1 | E9: Predios cerrados, o Zonas industriales o logísticas | F9: 1 | G9: La localización geográfica donde se emplaza el depósito es segura en cuanto riesgos de seguridad patrimonial | K9: =+[2]IFT!F9 -> 1 | N9: 0.15 | O9: 0.5
A10: =A9+1 -> 2 | B10: 1.1 | C10: ENTORNO Y SEGURIDAD EXTERNA | D10: 1.1.2 | E10: Zona segura, con vigilancia de fuerzas públicas o privadas | F10: 1 | K10: =+[2]IFT!F10 -> 1 | N10: 0.35 | O10: 0.5
A11: =A10+1 -> 3 | B11: 1.1 | C11: ENTORNO Y SEGURIDAD EXTERNA | D11: 1.1.3 | E11: Zona provista de iluminación pública o propia. | F11: 1 | K11: =+[2]IFT!F11 -> 1 | N11: 0.3 | O11: 0.5
A12: =A11+1 -> 4 | B12: 1.1 | C12: ENTORNO Y SEGURIDAD EXTERNA | D12: 1.1.4 | E12: Existen cámaras de video externas pública o propia que cubran el ingreso principal o aledaños | F12: 1 | K12: =+[2]IFT!F12 -> 1 | N12: 0.2 | O12: 0.5
A13: =A12+1 -> 5 | B13: 1.2 | C13: ENTORNO - ACCESO | D13: 1.2.1 | E13: Capacidad de recibir unidades de alto tonelaje | F13: 1 | G13: La localización geográfica donde se emplaza el depósito permite / autoriza acceso a vehículos, inclusive de gran porte | H13: CRITICO 1 | K13: =+[2]IFT!F13 -> 1 | N13: 1 | O13: 0.35
A14: =A13+1 -> 6 | B14: 1.3 | C14: PREDIO Y CIRCULACION | D14: 1.3.2 | E14: Entorno sin problemas de congestionamiento de tráfico | F14: 1 | G14: Los accesos / calles internas del predio - o del entorno del depósito o vía pública - permiten la circulación segura de vehículos y otro equipamiento de maniobra. | K14: =+[2]IFT!F14 -> 1 | N14: 0.3 | O14: 0.15
A15: =A14+1 -> 7 | B15: 1.3 | C15: PREDIO Y CIRCULACION | D15: 1.3.3 | E15: Poseen alero o permiten el ingreso de la culata de los vehiculos para la carga/descarga en condiciones climáticas desfavorables | F15: 0 | I15: Sin alero. | K15: =+[2]IFT!F15 -> 1 | N15: 0.2 | O15: 0.15
A16: =A15+1 -> 8 | B16: 1.3 | C16: PREDIO Y CIRCULACION | D16: 1.3.4 | E16: Fácil maniobrabilidad | F16: 1 | K16: =+[2]IFT!F16 -> 1 | N16: 0.3 | O16: 0.15
A17: =A16+1 -> 9 | B17: 1.3 | C17: PREDIO Y CIRCULACION | D17: 1.3.5 | E17: Calles y accesos en buen estado, sin pendientes, consolidados o asfaltados | F17: 0 | I17: Calles de ripio. Usan escolta para cuidar cables y estructuras vecinas. | K17: =+[2]IFT!F17 -> 1 | N17: 0.2 | O17: 0.15
B19: 2 | C19: EDIFICACION | F19: =SUMPRODUCT(F20:F38,N20:N38,O20:O38) -> 0.925 | K19: =SUMPRODUCT(K20:K38,N20:N38,O20:O38) -> 0.98 | N19: =+[1]MATRIZ!$G$9 -> 0.4 | O19: =+F19*N19 -> 0.37
A20: =A17+1 -> 10 | B20: 2.1 | C20: SEGURIDAD INTERNA | D20: 2.1.1 | E20: Sistema de Alarmas en depósito y oficinas | F20: 1 | G20: La seguridad patrimonial se garantiza mediante infraestructura electrónica y/o actividades de vigilancia | K20: =+[2]IFT!F20 -> 1 | N20: 0.6 | O20: 0.05
A21: =A20+1 -> 11 | B21: 2.1 | C21: SEGURIDAD INTERNA | D21: 2.1.2 | E21: Cámaras de Video en distintos sectores, con grabación y registro | F21: 1 | K21: =+[2]IFT!F21 -> 1 | N21: 0.4 | O21: 0.05
A22: =A21+1 -> 12 | B22: 2.2 | C22: LAY OUT - CAPACIDAD Y MODULACION | D22: 2.2.1 | E22: Días hábiles promedio 6 meses de venta almacenados en la bodega (MinImo 21 dias) | F22: 1 | G22: La capacidad del depósito es adecuada para el volumen de ventas , asegura el flujo físico continuo y permite mantener la cobertura de stock definida por Arcor. | H22: CRITICO 2 | I22: Este componente se valida con información provista por ARCOR | K22: =+[2]IFT!F22 -> 1 | N22: 1 | O22: 0.5
A23: =A22+1 -> 13 | B23: 2.3 | C23: TECHOS y PAREDES: ESTADO | D23: 2.3.1 | E23: Techo aislado y/o revestido, bien conservado | F23: 1 | G23: Las paredes y los techos del depósito se encuentran en buen estado y cuentan con elementos que garantizan las condiciones de conservación de los productos , definidos por Arcor. Temperatura 35°C (máxima promedio). | K23: =+[2]IFT!F23 -> 1 | N23: 0.35 | O23: 0.1
A24: =A23+1 -> 14 | B24: 2.3 | C24: TECHOS y PAREDES: ESTADO | D24: 2.3.2 | E24: Paredes aisladas y/o revestidas, bien conservadas, que no permitan la acumulación de tierra o plagas | F24: 1 | K24: =+[2]IFT!F24 -> 1 | N24: 0.35 | O24: 0.1
A25: =A24+1 -> 15 | B25: 2.3 | C25: TECHOS y PAREDES: ESTADO | D25: 2.3.3 | E25: Cuenta con extractores eólicos y/o ventilación forzada | F25: 0 | K25: =+[2]IFT!F25 -> 0 | N25: 0.2 | O25: 0.1
A26: =A25+1 -> 16 | B26: 2.3 | C26: TECHOS y PAREDES: ESTADO | D26: 2.3.4 | E26: Posee termómetro en sector Secos, (no se permiten termometros de mercurio) | F26: 1 | K26: =+[2]IFT!F26 -> 1 | N26: 0.1 | O26: 0.1
A27: =A26+1 -> 17 | B27: 2.4 | C27: PISOS y JUNTAS: ESTADO | D27: 2.4.1 | E27: Posee terminación alisada (a llana) | F27: 1 | G27: Los pisos y juntas interiores del depósito son adecuados, en buen estado, garantizando y asegurando la operación. | K27: =+[2]IFT!F27 -> 1 | N27: 0.15 | O27: 0.225
A28: =A27+1 -> 18 | B28: 2.4 | C28: PISOS y JUNTAS: ESTADO | D28: 2.4.2 | E28: Las juntas poseen relleno (compuesto elástico ) y/o protección metálica que no genere golpes al transito de apiladoras o transpaletas | F28: 0 | I28: Mejorar piso en zona de recepción. Se Visualizan grietas | K28: =+[2]IFT!F28 -> 1 | N28: 0.2 | O28: 0.225
A29: =A28+1 -> 19 | B29: 2.4 | C29: PISOS y JUNTAS: ESTADO | D29: 2.4.3 | E29: No posee desniveles entre los paños | F29: 1 | K29: =+[2]IFT!F29 -> 1 | N29: 0.3 | O29: 0.225
A30: =A29+1 -> 20 | B30: 2.4 | C30: PISOS y JUNTAS: ESTADO | D30: 2.4.4 | E30: El piso no desprende polvillo y/o no se visualizan grietas | F30: 1 | K30: =+[2]IFT!F30 -> 1 | N30: 0.35 | O30: 0.225
A31: =A30+1 -> 21 | B31: 2.5 | C31: ABERTURAS | D31: 2.5.1 | E31: Cuenta con 2 o más portones | F31: 1 | G31: El depósito cuenta con al menos 2 portones e ingreso peatonal independiente | K31: =+[2]IFT!F31 -> 1 | N31: 0.6 | O31: 0.05
A32: =A31+1 -> 22 | B32: 2.5 | C32: =+C31 -> ABERTURAS | D32: 2.5.2 | E32: Posee ingreso de personal independiente de la carga | F32: 1 | K32: =+[2]IFT!F32 -> 1 | N32: 0.4 | O32: 0.05
A33: =A32+1 -> 23 | B33: 2.6 | C33: ILUMNACIÓN | D33: 2.6.1 | E33: Se encuentran por encima del nivel más alto de almacenamiento | F33: 1 | G33: El depósito cuenta con lluminación adecuada para garantizar una operación logística eficaz y segura | K33: =+[2]IFT!F33 -> 1 | N33: 0.4 | O33: 0.05
A34: =A33+1 -> 24 | B34: 2.6 | C34: ILUMNACIÓN | D34: 2.6.2 | E34: Se encuentran centradas a lo largo de los pasillos | F34: 1 | K34: =+[2]IFT!F34 -> 1 | N34: 0.3 | O34: 0.05
A35: =A34+1 -> 25 | B35: 2.6 | C35: ILUMNACIÓN | D35: 2.6.3 | E35: No se perciben sectores oscuros que afecten la operación | F35: 1 | K35: =+[2]IFT!F35 -> 1 | N35: 0.1 | O35: 0.05
A36: =A35+1 -> 26 | B36: 2.6 | C36: ILUMNACIÓN | D36: 2.6.4 | E36: Se aprovecha la luz natural para la operación diurna sin aumento considerable de la temperatura en el interior | F36: 0 | I36: no se visualizan ventanas. Con los portones cerrados se ve oscuro y deben usar luz artificial | K36: =+[2]IFT!F36 -> 1 | N36: 0.2 | O36: 0.05
A37: =A36+1 -> 27 | B37: 2.7 | C37: DESAGUES | D37: 2.7.1 | E37: Se ubican en el exterior del edificio | F37: 1 | G37: El depósito cuenta con desagües que permiten evacuar el agua acumulada por lluvia | K37: =+[2]IFT!F37 -> 1 | N37: 0.5 | O37: 0.025
A38: =A37+1 -> 28 | B38: 2.7 | C38: DESAGUES | D38: 2.7.2 | E38: Se encuentran en buen estado (no se visualizan manchas de humedad), con rejillas de protección | F38: 1 | K38: =+[2]IFT!F38 -> 1 | N38: 0.5 | O38: 0.025
B40: 3 | C40: ALMACENAMIENTO Y MANIPULEO | F40: =SUMPRODUCT(F41:F56,N41:N56,O41:O56) -> 0.91 | K40: =SUMPRODUCT(K41:K56,N41:N56,O41:O56) -> 1 | N40: =+[1]MATRIZ!$G$10 -> 0.275 | O40: =+F40*N40 -> 0.25025
A41: =A38+1 -> 29 | B41: 3.1 | C41: EPPS Y EXTINGUIDORES | D41: 3.1.1 | E41: Uso correcto de EPPS (zapatos o casco según reglamentación local vigente) | F41: 1 | G41: Uso correcto de EPP (zapatos, cascos) y extintores en correctas condiciones | H41: CRITICO 3 | K41: =+[2]IFT!F41 -> 1 | N41: 0.4 | O41: 0.5
A42: =A41+1 -> 30 | B42: 3.1 | C42: EPPS y Extinguidores | D42: 3.1.2 | E42: Extintores bien ubicados y en período de vencimiento | F42: 1 | H42: =+H41 -> CRITICO 3 | K42: =+[2]IFT!F42 -> 1 | N42: 0.6 | O42: 0.5
A43: =A42+1 -> 31 | B43: 3.2 | C43: POP Y MOBILIARIO | D43: 3.2.1 | E43: Los freezers y/o mobiliarios usados se encuentran en condiciones de higiene adecuadas | F43: N/A | G43: La infraestructura del depósito permite el almacenamiento de material promocional y de conservación en punto de venta (POP, mobiliario, freezers, etc) en un lugar aislado de la mercadería y seguro para la conservación y rotación de los mismos. | K43: =+[2]IFT!F43 -> 1 | N43: 0 | O43: 0.3
...

Sheet PLG
Z1: 0
F2: EV25 | K2: AE 25 | Z2: 1
E3: =+B5 -> Area de interés : Procesos Logísticos | F3: =+O8+O18+O28+O36+O48+O56 -> 0.96 | K3: =+K8*N8+K18*N18+K28*N28+K36*N36+K48*N48+K56*N56 -> 0.955 | N3: AREA en programa | O3: 0.25 | Z3: N/A
E4: Programa | F4: =+F3*O3 -> 0.24 | G4: =+F4+IFT!F4+GST!F4+IDP!F4 -> 0.95677083 | K4: =+K3*O3 -> 0.23875 | L4: =+K4+IFT!K4+GST!K4+IDP!K4 -> 0.959315 | Z4: NA - 1
B5: Area de interés : Procesos Logísticos | N5: Ponderaciones en Area | Z5: NA - 0
B6: NRO. | C6: Buena Practica Logistica | E6: Componente | F6: EV25 | G6: Declaración de Buena Practica | H6: Critico | I6: Comentarios Evaluación | K6: AE 25 | N6: comp en el atributo | O6: Peso BPL
B8: 6 | C8: ABASTECIMIENTO Y RECEPCIÓN | F8: =SUMPRODUCT(F9:F16,N9:N16,O9:O16) -> 1 | K8: =SUMPRODUCT(K9:K16,N9:N16,O9:O16) -> 1 | N8: =+[1]MATRIZ!$G$13 -> 0.2 | O8: =+N8*F8 -> 0.2
A9: =+IFT!A66+1 -> 51 | B9: 6.1 | C9: PLANIFICACIÓN DE LAS COMPRAS | D9: 6.1.1 | E9: Se informa/comunica las compras ( de volumen mayor a los normal o excepcionales)a Logística para que pueda planificar la operación de descarga y espacio necesario.(Registro, email, etc) | F9: 1 | G9: Logística interviene en el proceso de planificación de necesidades de Compras. | K9: =+[2]PLG!F9 -> 1 | N9: 0.6 | O9: 0.45
A10: =A9+1 -> 52 | B10: 6.1 | C10: PLANIFICACIÓN DE LAS COMPRAS | D10: 6.1.2 | E10: Realizan compras proporcionales y distribuidas dentro del mes | F10: 1 | K10: =+[2]PLG!F10 -> 1 | N10: 0.4 | O10: 0.45
A11: =A10+1 -> 53 | B11: 6.2 | C11: ACTIVACION DEL ABASTECIMIENTO | D11: 6.2.1 | E11: Logística recibe el IAD | F11: 1 | G11: El proceso de activación del abastecimiento minimiza arribos imprevistos o demoras exageradas. | K11: =+[2]PLG!F11 -> 1 | N11: 1 | O11: 0.3
A12: =A11+1 -> 54 | B12: 6.3 | C12: COORDINACIÓN DEL ABASTECIMIENTO | D12: 6.3.1 | E12: Previsión de espacio para el guardado/almacenamiento y/o reordenamiento de la mercadería | F12: 1 | G12: El proceso de coordinación del abastecimiento permite planificar recursos para la descarga. | H12: CRITICO 5 | K12: =+[2]PLG!F12 -> 1 | N12: 0.3 | O12: 0.15
A13: =A12+1 -> 55 | B13: 6.3 | C13: COORDINACIÓN DEL ABASTECIMIENTO | D13: 6.3.2 | E13: Previsión de personas y equipo (Apilador/Autoelevador) necesarias para la descarga | F13: 1 | H13: CRITICO 5 | K13: =+[2]PLG!F13 -> 1 | N13: 0.3 | O13: 0.15
A14: =A13+1 -> 56 | B14: 6.3 | C14: COORDINACIÓN DEL ABASTECIMIENTO | D14: 6.3.3 | E14: Cuenta con una ventana horaria de 8hs para recepción de mercadería | F14: 1 | H14: CRITICO 5 | K14: =+[2]PLG!F14 -> 1 | N14: 0.2 | O14: 0.15
A15: =A14+1 -> 57 | B15: 6.3 | C15: COORDINACIÓN DEL ABASTECIMIENTO | D15: 6.3.4 | E15: Descarga en lugares definidos | F15: 1 | H15: CRITICO 5 | K15: =+[2]PLG!F15 -> 1 | N15: 0.2 | O15: 0.15
A16: =A15+1 -> 58 | B16: 6.4 | C16: RECEPCION | D16: 6.4.1 | E16: Las novedades se transmiten a Logística de Arcor por correo | F16: 1 | G16: El proceso de control de recepción garantiza integridad de la mercadería y transmisión a Arcor de discrepancias | K16: =+[2]PLG!F16 -> 1 | N16: 1 | O16: 0.1
B18: 7 | C18: ALMACENAMIENTO Y MANIPULEO | F18: =SUMPRODUCT(F19:F26,N19:N26,O19:O26) -> 0.75 | K18: =SUMPRODUCT(K19:K26,N19:N26,O19:O26) -> 1 | N18: =+[1]MATRIZ!$G$14 -> 0.1 | O18: =+N18*F18 -> 0.075
A19: =+A16+1 -> 59 | B19: 7.1 | C19: ORGANIZACIÓN DEL LAY OUT | D19: 7.1.1 | E19: Frecuencia definida documentada de revisión y/o modificación del lay-out (minimo cada 3 meses, maximo cada 6 meses) | F19: 0 | G19: La Organización del lay out optimiza el guardado, rotación, reposición y preparado de mercadería | I19: Lo ordena el sistema Ramdon. No se realiza modificación | K19: =+[2]PLG!F19 -> 1 | N19: 0.5 | O19: 0.5
A20: =A19+1 -> 60 | B20: 7.1 | C20: =+C19 -> ORGANIZACIÓN DEL LAY OUT | D20: 7.1.2 | E20: Pasillos organizados por algun criterio logico (Negocio, ABC, familia, etc) | F20: 1 | K20: =+[2]PLG!F20 -> 1 | N20: 0.5 | O20: 0.5
A21: =A20+1 -> 61 | B21: 7.2 | C21: IDENTIFICACION DEL LAY OUT | D21: 7.2.1 | E21: Cada área del lay out se encuentra demarcada (Zonas pintadas en el piso) | F21: 1 | G21: Se encuentran definidas e identificadas las zonas del lay out | K21: =+[2]PLG!F21 -> 1 | N21: 0.3 | O21: 0.15
A22: =A21+1 -> 62 | B22: 7.2 | C22: IDENTIFICACION DEL LAY OUT | D22: 7.2.2 | E22: Áreas principales identificadas (Recepción-Despacho-Devoluciones-Mercadería no comercializable-picking/almacenamiento) | F22: 1 | K22: =+[2]PLG!F22 -> 1 | N22: 0.4 | O22: 0.15
A23: =A22+1 -> 63 | B23: 7.2 | C23: =+C22 -> IDENTIFICACION DEL LAY OUT | D23: 7.2.3 | E23: No hay superposición entre áreas críticas (Despacho y Recepción por ej) | F23: 1 | K23: =+[2]PLG!F23 -> 1 | N23: 0.3 | O23: 0.15
A24: =A23+1 -> 64 | B24: 7.3 | C24: IDENTIFICACION DEL LAY OUT | D24: 7.3.1 | E24: Control de rotación y vencimientos junto al inventario rotativo y/o auditorias de 5S | F24: 1 | G24: Se garantiza identificación y rotación de la mercadería (FEFO), en sectores de almacenamiento como de preparado | K24: =+[2]PLG!F24 -> 1 | N24: 0.4 | O24: 0.35
A25: =A24+1 -> 65 | B25: 7.3 | C25: ROTACION | D25: 7.3.2 | E25: Se lleva registro de las unidades vencidas | F25: 1 | K25: =+[2]PLG!F25 -> 1 | N25: 0.3 | O25: 0.35
A26: =A25+1 -> 66 | B26: 7.3 | C26: =+C25 -> ROTACION | D26: 7.3.2 | E26: Se informa sobre productos proximos a vencer a fin de tomar acciones | F26: 1 | K26: =+[2]PLG!F26 -> 1 | N26: 0.3 | O26: 0.35
B28: 8 | C28: REPOSICION INVENTARIOS | F28: =SUMPRODUCT(F29:F34,N29:N34,O29:O34) -> 1 | K28: =SUMPRODUCT(K29:K34,N29:N34,O29:O34) -> 1 | N28: =+[1]MATRIZ!$G$15 -> 0.25 | O28: =+N28*F28 -> 0.25
A29: =+A26+1 -> 67 | B29: 8.1 | C29: REPOSICIÓN DE MERCADERIA | D29: 8.1.1 | E29: Logística o personal designado supervisa por turno o por día con algún criterio (Por ej: Productos A) | F29: 1 | G29: Está estandarizado el proceso de reposición de mercadería desde almacenamiento a picking. | K29: =+[2]PLG!F29 -> 1 | N29: 0.3 | O29: 0.2
A30: =A29+1 -> 68 | B30: 8.1 | C30: REPOSICIÓN DE MERCADERIA | D30: 8.1.2 | E30: Posiciones fijas de pickeo con capacidades definidas y/o frecuencias de reposición. | F30: 1 | K30: =+[2]PLG!F30 -> 1 | N30: 0.4 | O30: 0.2
A31: =A30+1 -> 69 | B31: 8.1 | C31: =+C29 -> REPOSICIÓN DE MERCADERIA | D31: 8.1.3 | E31: Se verifica el volumen de la posición de picking con una frecuencia determinada (minimo cada 3 meses, maximo cada 6 meses) | F31: 1 | K31: =+[2]PLG!F31 -> 1 | N31: 0.3 | O31: 0.2
A32: =+A31+1 -> 70 | B32: 8.2 | C32: =+C33 -> INVENTARIOS ROTATIVOS | D32: 8.2.1 | E32: Se analizan causas al finalizar. Se registran acciones | F32: 1 | G32: Se realizan inventarios rotativos para asegurar confiabilidad del stock | H32: CRITICO 6 | K32: =+[2]PLG!F32 -> 1 | N32: 0.4 | O32: 0.8
A33: =A32+1 -> 71 | B33: 8.2 | C33: INVENTARIOS ROTATIVOS | D33: 8.2.2 | E33: Criterio definido de selección de items (ABC, rotativo,negocio, pasillo, etc.). Se toman y/o verifican fechas de vencimientos. | F33: 1 | H33: CRITICO 6 | I33: Viernes por familia. | K33: =+[2]PLG!F33 -> 1 | N33: 0.35 | O33: 0.8
A34: =A33+1 -> 72 | B34: 8.2 | C34: =+C32 -> INVENTARIOS ROTATIVOS | D34: 8.2.3 | E34: Se realizan con una frecuencia definida, mínima mensual | F34: 1 | H34: CRITICO 6 | I34: Se completa en un mes el 100% del deposito | K34: =+[2]PLG!F34 -> 1 | N34: 0.25 | O34: 0.8
B36: 9 | C36: CONSOLIDADOS Y PEDIDOS | F36: =SUMPRODUCT(F37:F46,N37:N46,O37:O46) -> 1 | K36: =SUMPRODUCT(K37:K46,N37:N46,O37:O46) -> 0.88 | N36: =+[1]MATRIZ!$G$16 -> 0.25 | O36: =+N36*F36 -> 0.25
A37: =+A34+1 -> 73 | B37: 9.1 | C37: TRANSMISION DE PEDIDOS | D37: 9.1.1 | E37: Ventana horaria establecida para el corte de pedidos | F37: 1 | G37: Existe una transmisión de pedidos en forma continua o con algún criterio | K37: =+[2]PLG!F37 -> 1 | N37: 0.6 | O37: 0.1
A38: =A37+1 -> 74 | B38: 9.1 | C38: =+C37 -> TRANSMISION DE PEDIDOS | D38: 9.1.2 | E38: Realiza analisis frecuentes relacionado a desvios en el corte de pedidos | F38: 1 | K38: =+[2]PLG!F38 -> 1 | N38: 0.4 | O38: 0.1
A39: =A38+1 -> 75 | B39: 9.2 | C39: ARMADO Y ASIGNACIÓN DE CONSOLIDADOS Y/O PEDIDOS | D39: 9.2.1 | E39: El ordenamiento físico de los productos coincide con el consolidado | F39: 1 | G39: La generación de consolidados se hace por criterios definidos (cortes x $; cant Bultos; reparto, vendedor, etc) optimizando los recursos de la distribuidora | K39: =+[2]PLG!F39 -> 1 | N39: 0.5 | O39: 0.15
A40: =A39+1 -> 76 | B40: 9.2 | C40: =+C39 -> ARMADO Y ASIGNACIÓN DE CONSOLIDADOS Y/O PEDIDOS | D40: 9.2.2 | E40: Se generan los consolidados aplicando criterios (Logísticos)de corte a partir de los pedidos ingresados-Solo para los que trabajan pedido por pedido | F40: 1 | K40: =+[2]PLG!F40 -> 1 | N40: 0.5 | O40: 0.15
A41: =+A40+1 -> 77 | B41: 9.3 | C41: =+C42 -> CONTROL DE CONSOLIDADO | D41: 9.3.1 | E41: Se registran los errores y usuarios para mejorar el proceso | F41: 1 | G41: Existe un control de los consolidados preparados que evita las diferencias entre la orden y la preparación fisica | K41: =+[2]PLG!F41 -> 0 | N41: 0.3 | O41: 0.4
A42: =A41+1 -> 78 | B42: 9.3 | C42: CONTROL DE CONSOLIDADO | D42: 9.3.2 | E42: Se conserva en forma transitoria registro de control del consolidado | F42: 1 | K42: =+[2]PLG!F42 -> 1 | N42: 0.45 | O42: 0.4
A43: =A42+1 -> 79 | B43: 9.3 | C43: =+C41 -> CONTROL DE CONSOLIDADO | D43: 9.3.3 | E43: Existe un metodo de control de consolidado | F43: 1 | K43: =+[2]PLG!F43 -> 1 | N43: 0.25 | O43: 0.4
A44: =+A43+1 -> 80 | B44: 9.4 | C44: =+C45 -> ARMADO DE PEDIDOS | D44: 9.4.1 | E44: El pedido contiene identificación de bultos, cliente, zona de reparto, factura, o alguna identificación que facilite la carga | F44: 1 | G44: El control del armado evita las diferencias entre la orden y la preparación fisica | K44: =+[2]PLG!F44 -> 1 | N44: 0.3 | O44: 0.35
...

Sheet GST
Z1: 0
F2: EV25 | K2: AE 25 | Z2: 1
E3: =+B5 -> Area de interés : Gestión | F3: =+O8+O31+O42+O48+O52 -> 0.958 | K3: =+K8*N8+K31*N31+K42*N42+K48*N48+K52*N52 -> 0.9225 | N3: AREA en programa | O3: 0.2 | Z3: N/A
E4: Programa | F4: =+F3*O3 -> 0.1916 | G4: =+IFT!F4+PLG!F4+GST!F4+IDP!F4 -> 0.95677083 | K4: =+K3*O3 -> 0.1845 | L4: =+IFT!K4+PLG!K4+GST!K4+IDP!K4 -> 0.959315 | Z4: NA - 1
B5: Area de interés : Gestión | N5: Ponderaciones en Area | Z5: NA - 0
B6: NRO. | C6: Buena Practica Logistica | E6: Componente | F6: EV25 | G6: Declaración de Buena Practica | H6: Critico | I6: Comentarios Evaluación | K6: AE 25 | N6: comp en el atributo | O6: Peso BPL
B8: 12 | C8: ORGANIZACIÓN | F8: =SUMPRODUCT(F9:F29,N9:N29,O9:O29) -> 1 | K8: =SUMPRODUCT(K9:K29,N9:N29,O9:O29) -> 0.85 | N8: =+[1]MATRIZ!$G$19 -> 0.25 | O8: =+N8*F8 -> 0.25
A9: =+PLG!A60+1 -> 93 | B9: 12.1 | C9: HERRAMIENTAS DE GESTION | D9: 12.1.1 | E9: Dispone de alguna herramienta informatica y la utiliza en el depósito | F9: N/A | G9: Cuenta con herramientas de le permita gestionar las operaciones del depósito (warehouse) , logistica de salida y reversa (Arcortruck) | K9: =+[2]GST!F9 -> N/A | N9: 0.2 | O9: 0
A10: =A9+1 -> 94 | B10: 12.1 | C10: HERRAMIENTAS DE GESTION | D10: 12.1.2 | E10: Cuenta con la aplicación de Arcortrukc para gestionar las entregas , rechazos y/o devoluciones de los clientes | F10: N/A | K10: =+[2]GST!F10 -> N/A | N10: 0.2 | O10: 0
A11: =A10+1 -> 95 | B11: 12.1 | C11: HERRAMIENTAS DE GESTION | D11: 12.1.3 | E11: Utiliza el Modulo Recepción | F11: N/A | K11: =+[2]GST!F11 -> N/A | N11: 0.1 | O11: 0
A12: =A11+1 -> 96 | B12: 12.1 | C12: HERRAMIENTAS DE GESTION | D12: 12.1.4 | E12: Utiliza el Modulo Inventario | F12: N/A | K12: =+[2]GST!F12 -> N/A | N12: 0.1 | O12: 0
A13: =A12+1 -> 97 | B13: 12.1 | C13: HERRAMIENTAS DE GESTION | D13: 12.1.5 | E13: Utiliza el Modulo Picking | F13: N/A | K13: =+[2]GST!F13 -> N/A | N13: 0.2 | O13: 0
A14: =A13+1 -> 98 | B14: 12.1 | C14: HERRAMIENTAS DE GESTION | D14: 12.1.6 | E14: Utiliza el Modulo Control de Consolidados | F14: N/A | K14: =+[2]GST!F14 -> N/A | N14: 0.1 | O14: 0
A15: =A14+1 -> 99 | B15: 12.1 | C15: HERRAMIENTAS DE GESTION | D15: 12.1.7 | E15: Utiliza el Modulo Armado de Pedidos | F15: N/A | K15: =+[2]GST!F15 -> N/A | N15: 0.1 | O15: 0
A16: =+A15+1 -> 100 | B16: 12.2 | C16: ORGANIGRAMAS Y PERFILES | D16: 12.2.1 | E16: Se encuentran comunicados | F16: 1 | G16: Existe un Organigrama que establece funciones y jerarquías en la distribuidora, incluyendo los perfiles de puestos principales | I16: buen manuan de procesos y perfiles. Pedir explicación sobre comunicación | K16: =+[2]GST!F16 -> 0 | N16: 0.3 | O16: 0.3
A17: =+A16+1 -> 101 | B17: 12.2 | C17: ORGANIGRAMAS Y PERFILES | D17: 12.2.2 | E17: Se encuentra definido y documentado el perfil del puesto de MML logística | F17: 1 | K17: =+[2]GST!F17 -> 0 | N17: 0.2 | O17: 0.3
A18: =+A17+1 -> 102 | B18: 12.2 | C18: ORGANIGRAMAS Y PERFILES | D18: 12.2.3 | E18: Se encuentran definidos los perfiles de puestos principales (comercial y administrativo) | F18: 1 | K18: =+[2]GST!F18 -> 1 | N18: 0.15 | O18: 0.3
A19: =+A18+1 -> 103 | B19: 12.2 | C19: ORGANIGRAMAS Y PERFILES | D19: 12.2.4 | E19: El organigrama se encuentra definido y documentado por la distribuidora | F19: 1 | K19: =+[2]GST!F19 -> 1 | N19: 0.35 | O19: 0.3
A20: =+A19+1 -> 104 | B20: 12.3 | C20: PROCESOS DOCUMENTADOS | D20: 12.3.1 | E20: Cuenta con el Procedimiento Proceso de Recepción y Control de Mercadería | F20: 1 | G20: Los procesos logísticos se encuentran documentados y actualizados. Sirven para evaluar desempeño del proceso y para induccion de nuevos recursos | H20: CRITICO 7 | I20: Revisar fecha para actualizar. Completar responsables | K20: =+[2]GST!F20 -> 1 | N20: 0.1 | O20: 0.7
A21: =+A20+1 -> 105 | B21: 12.3 | C21: PROCESOS DOCUMENTADOS | D21: 12.3.2 | E21: Cuenta con el Procedimiento Proceso de Reposición de Productos en Picking | F21: 1 | H21: CRITICO 7 | K21: =+[2]GST!F21 -> 1 | N21: 0.1 | O21: 0.7
A22: =+A21+1 -> 106 | B22: 12.3 | C22: PROCESOS DOCUMENTADOS | D22: 12.3.3 | E22: Cuenta con el Procedimiento Proceso de Almacenamiento de Productos | F22: 1 | H22: CRITICO 7 | K22: =+[2]GST!F22 -> 1 | N22: 0.1 | O22: 0.7
A23: =+A22+1 -> 107 | B23: 12.3 | C23: PROCESOS DOCUMENTADOS | D23: 12.3.4 | E23: Cuenta con el Procedimiento Proceso de Armado y Control de Consolidados | F23: 1 | H23: CRITICO 7 | K23: =+[2]GST!F23 -> 1 | N23: 0.1 | O23: 0.7
A24: =+A23+1 -> 108 | B24: 12.3 | C24: PROCESOS DOCUMENTADOS | D24: 12.3.5 | E24: Cuenta con el Procedimiento Proceso de Armado de Pedidos | F24: 1 | H24: CRITICO 7 | K24: =+[2]GST!F24 -> 1 | N24: 0.1 | O24: 0.7
A25: =+A24+1 -> 109 | B25: 12.3 | C25: PROCESOS DOCUMENTADOS | D25: 12.3.6 | E25: Cuenta con el Procedimiento Proceso de Control de hojas de ruta y carga de pedidos | F25: 1 | H25: CRITICO 7 | K25: =+[2]GST!F25 -> 1 | N25: 0.1 | O25: 0.7
A26: =+A25+1 -> 110 | B26: 12.3 | C26: PROCESOS DOCUMENTADOS | D26: 12.3.7 | E26: Cuenta con el Procedimiento Proceso de Control de Inventario | F26: 1 | H26: CRITICO 7 | K26: =+[2]GST!F26 -> 1 | N26: 0.1 | O26: 0.7
A27: =+A26+1 -> 111 | B27: 12.3 | C27: PROCESOS DOCUMENTADOS | D27: 12.3.8 | E27: Cuenta con el Procedimiento Proceso de Control de Hoja de Ruta y Logistica de Reversa | F27: 1 | H27: CRITICO 7 | K27: =+[2]GST!F27 -> 1 | N27: 0.1 | O27: 0.7
A28: =+A27+1 -> 112 | B28: 12.3 | C28: PROCESOS DOCUMENTADOS | D28: 12.3.9 | E28: Los responsables del proceso conocen el procedimiento, el mismo coincide con el proceso | F28: 1 | H28: CRITICO 7 | K28: =+[2]GST!F28 -> 1 | N28: 0.1 | O28: 0.7
A29: =+A28+1 -> 113 | B29: 12.3 | C29: PROCESOS DOCUMENTADOS | D29: 12.3.10 | E29: El formato del procedimiento se ajusta al modelo estandar propuesto por Arcor | F29: 1 | H29: CRITICO 7 | K29: =+[2]GST!F29 -> 1 | N29: 0.1 | O29: 0.7
B31: 13 | C31: PLANIFICACION | F31: =SUMPRODUCT(F32:F40,N32:N40,O32:O40) -> 1 | K31: =SUMPRODUCT(K32:K40,N32:N40,O32:O40) -> 1 | N31: =+[1]MATRIZ!$G$20 -> 0.25 | O31: =+N31*F31 -> 0.25
A32: =+A29+1 -> 114 | B32: 13.1 | C32: PLANIFICACIÓN TÁCTICA | D32: 13.1.1 | E32: Logistica participa de reuniones con Ventas y Administracion, en las cuales se definen objetivos anuales y/o mensuales | F32: 1 | G32: Se planifican tareas en forma periodica (diarias, semanal, quincenal, mensual) en el sector, distribuyendo actividades y dejando establecidas las responsabilidades para cada uno. | K32: =+[2]GST!F32 -> 1 | N32: 0.4 | O32: 0.45
A33: =A32+1 -> 115 | B33: 13.1 | C33: PLANIFICACIÓN TÁCTICA | D33: 13.1.2 | E33: Se realiza el seguimiento de la planificación en forma períodica (semanal, quincenal o mensual) evaluando el alcance de los resultados. | F33: 1 | I33: Incorporar armado de minuta con detalle de participantes, motivo, y luego plasmar en un plan de acción | K33: =+[2]GST!F33 -> 1 | N33: 0.3 | O33: 0.45
A34: =A33+1 -> 116 | B34: 13.1 | C34: PLANIFICACIÓN TÁCTICA | D34: 13.1.3 | E34: Las acciones surgidas de la planificación quedan plasmadas en un plan de acción | F34: 1 | K34: =+[2]GST!F34 -> 1 | N34: 0.3 | O34: 0.45
A35: =A34+1 -> 117 | B35: 13.2 | C35: PLANIFICACIÓN OPERATIVA | D35: 13.2.1 | E35: Se registran e informan las acciones o novedades en un pizarrón o avisadores. | F35: 1 | G35: Se planifican tareas en forma periodica (diarias, semanal, quincenal, mensual) en el sector, distribuyendo actividades y dejando establecidas las responsabilidades para cada uno. | K35: =+[2]GST!F35 -> 1 | N35: 0.4 | O35: 0.15
A36: =A35+1 -> 118 | B36: 13.2 | C36: =+C35 -> PLANIFICACIÓN OPERATIVA | D36: 13.2.2 | E36: Se realizan reuniones periódicas en el sector registrándose las decisiones en planes de acción | F36: 1 | K36: =+[2]GST!F36 -> 1 | N36: 0.6 | O36: 0.15
A37: =+A36+1 -> 119 | B37: 13.3 | C37: MANTENIMIENTO | D37: 13.3.1 | E37: Se planifica el mantenimiento preventivo de la infraestructura (desagües, portones, racks, techos) | F37: 1 | G37: La Distribuidora posee un plan de mantenimiento preventivo para equipamiento e Infraestructura | I37: Excelente plan | K37: =+[2]GST!F37 -> 1 | N37: 0.5 | O37: 0.4
A38: =+A37+1 -> 120 | B38: 13.3 | C38: MANTENIMIENTO | D38: 13.3.2 | E38: Se planifica el mantenimiento preventivo del grupo electrógeno | F38: N/A | I38: Excelente plan | K38: =+[2]GST!F38 -> N/A | N38: 0 | O38: 0.4
A39: =+A38+1 -> 121 | B39: 13.3 | C39: MANTENIMIENTO | D39: 13.3.3 | E39: Se planifica el mantenimiento preventivos del equipamiento logístico de manipuleo | F39: 1 | I39: Excelente plan | K39: =+[2]GST!F39 -> 1 | N39: 0.25 | O39: 0.4
A40: =+A39+1 -> 122 | B40: 13.3 | C40: MANTENIMIENTO | D40: 13.3.4 | E40: Se planifica el mantenimiento preventivo de flota propia o chequeo de tercerizada | F40: 1 | I40: Excelente plan | K40: =+[2]GST!F40 -> 1 | N40: 0.25 | O40: 0.4
B42: 14 | C42: INFORMACION Y COMUNICACIONES | F42: =SUMPRODUCT(F43:F46,N43:N46,O43:O46) -> 1 | K42: =SUMPRODUCT(K43:K46,N43:N46,O43:O46) -> 1 | N42: =+[1]MATRIZ!$G$21 -> 0.1 | O42: =+N42*F42 -> 0.1
A43: =+A40+1 -> 123 | B43: 14.1 | C43: INFORMACIÓN AL PERSONAL | D43: 14.1.1 | E43: La información en ella se encuentra actualizada | F43: 1 | G43: Existe cartelería en el depósito que permita dar información al personal sobre temas afines a la actividad logística (indicadores, gráficos, actividades, planes, avisos generales) | K43: =+[2]GST!F43 -> 1 | N43: 0.5 | O43: 0.7
...

Sheet IDP
Z1: 0
F2: EV25 | K2: AE 25 | Z2: 1
E3: =+B5 -> Area de interés : Integridad del Producto | F3: =+O8+O14+O33+O42+O49+O58 -> 0.97411111 | K3: =+K8*N8+K14*N14+K33*N33+K42*N42+K49*N49+K58*N58 -> 0.96021667 | N3: AREA en programa | O3: 0.3 | Z3: N/A
E4: Programa | F4: =+F3*O3 -> 0.29223333 | G4: =+F4+GST!F4+PLG!F4+IFT!F4 -> 0.95677083 | K4: =+K3*O3 -> 0.288065 | L4: =+K4+GST!K4+PLG!K4+IFT!K4 -> 0.959315 | Z4: NA - 1
B5: Area de interés : Integridad del Producto | N5: Ponderaciones en Area | Z5: NA - 0
B6: NRO. | C6: Buena Practica Logistica | E6: Componente | F6: EV25 | G6: Declaración de Buena Practica | H6: Critico | I6: Comentarios Evaluación | K6: AE 25 | N6: comp en el atributo | O6: Peso BPL
B8: 17 | C8: ABASTECIMIENTO Y RECEPCIÓN | F8: =SUMPRODUCT(F9:F12,N9:N12,O9:O12) -> 1 | K8: =SUMPRODUCT(K9:K12,N9:N12,O9:O12) -> 1 | N8: =+[1]MATRIZ!$G$24 -> 0.15 | O8: =+N8*F8 -> 0.15
A9: =+GST!A63+1 -> 140 | B9: 17.1 | C9: RECEPCION | D9: 17.1.1 | E9: Control general de la carga incluye vencimientos | F9: 1 | G9: Se realizan controles durante la recepción de productos restringiendo el ingresos de aquellos no aptos o en malas condiciones. | K9: =+[2]IDP!F9 -> 1 | N9: 0.5 | O9: 1
A10: =A9+1 -> 141 | B10: 17.1 | C10: RECEPCION | D10: 17.1.2 | E10: Control general de cantidad y estado de bultos recibidos | F10: 1 | K10: =+[2]IDP!F10 -> 1 | N10: 0.5 | O10: 1
A11: =A10+1 -> 142 | B11: 17.1 | C11: RECEPCION | D11: 17.1.3 | E11: Controlan y poseen un registro de la temperatura con la que arriba la carga de Helados | F11: N/A | K11: =+[2]IDP!F11 -> N/A | N11: 0 | O11: 1
A12: =A11+1 -> 143 | B12: 17.1 | C12: RECEPCION | D12: 17.1.4 | E12: Controlan y poseen un registro de la temperatura con la que arriba la carga de Refrigerados | F12: N/A | K12: =+[2]IDP!F12 -> N/A | N12: 0 | O12: 1
B14: 18 | C14: ALMACENAMIENTO Y MANIPULEO | F14: =SUMPRODUCT(F15:F31,N15:N31,O15:O31) -> 0.94444444 | K14: =SUMPRODUCT(K15:K31,N15:N31,O15:O31) -> 0.88886667 | N14: =+[1]MATRIZ!$G$25 -> 0.25 | O14: =+N14*F14 -> 0.23611111
A15: =+A12+1 -> 144 | B15: 18.1 | C15: ALMACENAMIENTO | D15: 18.1.1 | E15: Se identifican claramente los vencimientos. | F15: 1 | G15: Se garantiza la integridad del producto durante su almacenamiento. | K15: =+[2]IDP!F15 -> 1 | N15: 0.4 | O15: 0.16666667
A16: =A15+1 -> 145 | B16: 18.1 | C16: ALMACENAMIENTO | D16: 18.1.2 | E16: Los bultos almacenados se encuentran en buen estado de conservación, apilabilidad y separacion de la estiba contra la pared | F16: 1 | K16: =+[2]IDP!F16 -> 1 | N16: 0.4 | O16: 0.16666667
A17: =A16+1 -> 146 | B17: 18.1 | C17: ALMACENAMIENTO | D17: 18.1.3 | E17: Los productos que requieren acondicionamiento de temperatura (según Maestro de Articulos) se encuentran almacenados dentro de la cámara | F17: N/A | K17: =+[2]IDP!F17 -> N/A | N17: 0 | O17: 0.16666667
A18: =A17+1 -> 147 | B18: 18.1 | C18: ALMACENAMIENTO | D18: 18.1.4 | E18: No se encuentran pallets rotos, deteriorados, dañados almacenando mercadería | F18: 1 | K18: =+[2]IDP!F18 -> 1 | N18: 0.2 | O18: 0.16666667
A19: =+A18+1 -> 148 | B19: 18.2 | C19: CONTAMINACIÓN CRUZADA | D19: 18.2.1 | E19: En el depósito no se perciben olores extraños provenientes de estos químicos. | F19: 1 | G19: El depósito es apto para el almacenamiento seguro de producto sin riesgo de contaminaciones cruzadas con sustancias químicas o aromáticas. | K19: =+[2]IDP!F19 -> 1 | N19: 0.4 | O19: 0.27777778
A20: =A19+1 -> 149 | B20: 18.2 | C20: CONTAMINACIÓN CRUZADA | D20: 18.2.2 | E20: Los productos químicos se almacenan en lugares cerrados (armarios o gabinetes) | F20: 1 | K20: =+[2]IDP!F20 -> 1 | N20: 0.4 | O20: 0.27777778
A21: =A20+1 -> 150 | B21: 18.2 | C21: CONTAMINACIÓN CRUZADA | D21: 18.2.3 | E21: El lugar se encuentra identificado con cartelería | F21: 1 | K21: =+[2]IDP!F21 -> 0 | N21: 0.1 | O21: 0.27777778
A22: =A21+1 -> 151 | B22: 18.2 | C22: CONTAMINACIÓN CRUZADA | D22: 18.2.4 | E22: Se accede al lugar mediante uso de llave u otro elemento que garantice la inviolabilidad y no se evidencia concentración de aromas. | F22: 1 | K22: =+[2]IDP!F22 -> 1 | N22: 0.1 | O22: 0.27777778
A23: =+A22+1 -> 152 | B23: 18.3 | C23: CONTROL DE TEMPERATURAS | D23: 18.3.1 | E23: La temperatura de los productos secos no supera los 30°C (promedio máximo diario) y 35°C máximo y se garantiza mediante elemento de medición y registros | F23: 1 | G23: Se controlan las temperaturas de almacenamiento de los productos. | H23: CRITICO 9 | K23: =+[2]IDP!F23 -> 1 | N23: 0.5 | O23: 0.1111
A24: =A23+1 -> 153 | B24: 18.3 | C24: CONTROL DE TEMPERATURAS | D24: 18.3.2 | E24: Controlan y poseen un registro de la temperatura con la que arriba desde arcor | F24: 1 | H24: CRITICO 9 | K24: =+[2]IDP!F24 -> 1 | N24: 0.5 | O24: 0.1111
A25: =A24+1 -> 154 | B25: 18.3 | C25: CONTROL DE TEMPERATURAS | D25: 18.3.3 | E25: La temperatura de los productos congelados se encuentra en -22°C y se garantiza mediante registros | F25: N/A | K25: =+[2]IDP!F25 -> N/A | N25: 0 | O25: 0.1111
A26: =+A25+1 -> 155 | B26: 18.4 | C26: INSTRUMENTOS MEDICIÓN TEMPERATURA | D26: 18.4.1 | E26: Existe un registro de contrastación y/o calibración de termometros que garantice el correcto funcionamiento | F26: 0 | G26: Se mantiene un correcto mantenimiento de los instrumentos de medición de temperaturas y cuenta con un mecanismo de alerta. | I26: La calibración de la forma mostrada (rudimentaria, no profesional) deberia tener evidenciado regitros historicos. Se busca la implementación del proceso de contrastación. | K26: =+[2]IDP!F26 -> 0 | N26: 0.5 | O26: 0.0556
A27: =A26+1 -> 156 | B27: 18.4 | C27: INSTRUMENTOS MEDICIÓN TEMPERATURA | D27: 18.4.2 | E27: Los instrumentos de medición alertan ante variaciones inaceptables de temperatura | F27: 0 | K27: =+[2]IDP!F27 -> 0 | N27: 0.5 | O27: 0.0556
A28: =+A27+1 -> 157 | B28: 18.5 | C28: ROTACIÓN Y REPOSICIÓN | D28: 18.5.1 | E28: Se garantiza la inocuidad del producto evitando el contacto del envase primario o secundario con la madera u otro material contaminante | F28: 1 | G28: Se evita la contaminación del producto y garantiza su rotación en las tareas de reposición a zona de picking. | K28: =+[2]IDP!F28 -> 1 | N28: 0.5 | O28: 0.3333
A29: =A28+1 -> 158 | B29: 18.5 | C29: ROTACIÓN Y REPOSICIÓN | D29: 18.5.2 | E29: Se garantiza la correcta rotación FEFO por gestión visual o informática. | F29: 1 | K29: =+[2]IDP!F29 -> 1 | N29: 0.5 | O29: 0.3333
A30: =+A29+1 -> 159 | B30: 18.6 | C30: ILUMINACION | D30: 18.6.1 | E30: Las luminarias y aberturas de vidrio estan protegidas ante estallidos | F30: 1 | G30: Cuentan con protección aquellos elementos con materiales suceptibles de producir astillas ante su rotura. | K30: =+[2]IDP!F30 -> 0 | N30: 0.5 | O30: 0.0556
A31: =A30+1 -> 160 | B31: 18.6 | C31: ILUMINACION | D31: 18.6.2 | E31: Existen métodos de prevención de estallido y astillado en aberturas, etc | F31: 1 | K31: =+[2]IDP!F31 -> 1 | N31: 0.5 | O31: 0.0556
B33: 19 | C33: TRANSPORTE Y REPARTO | F33: =SUMPRODUCT(F34:F40,N34:N40,O34:O40) -> 1 | K33: =SUMPRODUCT(K34:K40,N34:N40,O34:O40) -> 1 | N33: =+[1]MATRIZ!$G$26 -> 0.25 | O33: =+N33*F33 -> 0.25
A34: =+A31+1 -> 161 | B34: 19.1 | C34: DESPACHO | D34: 19.1.1 | E34: Cuenta con una check-list para controlar las adecuadas condiciones de higiene, limpieza y acondicionamiento de la unidad contenedora del vehículo | F34: 1 | G34: Se preserva las condiciones del producto en las tareas de despacho y carga del transporte. | K34: =+[2]IDP!F34 -> 1 | N34: 0.4 | O34: 0.7
A35: =A34+1 -> 162 | B35: 19.1 | C35: DESPACHO | D35: 19.1.2 | E35: Se tienen en cuenta las condiciones de carga de los distintos productos (apilabilidad, peso, volumen, fragilidad, condiciones de temperatura, etc.) | F35: 1 | K35: =+[2]IDP!F35 -> 1 | N35: 0.6 | O35: 0.7
A36: =A35+1 -> 163 | B36: 19.1 | C36: DESPACHO | D36: 19.1.3 | E36: El distribuidor controla la temperatura al momento del despacho y durante la distribución en productos refrigerados. | F36: N/A | K36: =+[2]IDP!F36 -> N/A | N36: 0 | O36: 0.7
A37: =A36+1 -> 164 | B37: 19.2 | C37: DESPACHO LEGALES HIGIENE | D37: 19.2.1 | E37: Cuentan con un metodo/planilla de seguimiento de la documentación de los repartidores (Carnet de conducir y sanitario, tarjeta verde o azul, seguros, VTV o ITV, habilitaciones, etc) | F37: 1 | G37: Se tienen en cuenta los requisitos legales, de control e higiene para la flota de vehículos | K37: =+[2]IDP!F37 -> 1 | N37: 0.3 | O37: 0.3
A38: =A37+1 -> 165 | B38: 19.2 | C38: DESPACHO LEGALES HIGIENE | D38: 19.2.2 | E38: Los transportes son de uso exclusivo para alimentos y se encuentran habilitados por la autoridad compentente. | F38: 1 | K38: =+[2]IDP!F38 -> 1 | N38: 0.3 | O38: 0.3
A39: =A38+1 -> 166 | B39: 19.2 | C39: DESPACHO LEGALES HIGIENE | D39: 19.2.3 | E39: Los contenedores utilizados para el reparto conservan la integridad del producto. | F39: 1 | K39: =+[2]IDP!F39 -> 1 | N39: 0.4 | O39: 0.3
A40: =A39+1 -> 167 | B40: 19.2 | C40: DESPACHO LEGALES HIGIENE | D40: 19.2.4 | E40: El vehiculo que transporta helados cuenta con instrumento de medición de temperatura permitiendo su verificación en cabina. | F40: N/A | K40: =+[2]IDP!F40 -> N/A | N40: 0 | O40: 0.3
B42: 20 | C42: RETORNO Y/O DEVOLUCIONES | F42: =SUMPRODUCT(F43:F47,N43:N47,O43:O47) -> 1 | K42: =SUMPRODUCT(K43:K47,N43:N47,O43:O47) -> 1 | N42: =+[1]MATRIZ!$G$27 -> 0.15 | O42: =+N42*F42 -> 0.15
A43: =+A40+1 -> 168 | B43: 20.1 | C43: RECHAZOS | D43: 20.1.1 | E43: Está determinada la frecuencia de procesamiento de productos rechazados | F43: 1 | G43: Está definido el método de control y separación entre productos devueltos por el cliente que están aptos y no aptos. | H43: CRITICO 10 | K43: =+[2]IDP!F43 -> 1 | N43: 0.5 | O43: 0.4
A44: =A43+1 -> 169 | B44: 20.1 | C44: RECHAZOS | D44: 20.1.2 | E44: Los productos rechazados no aptos son rápidamente segregados de los productos aptos | F44: 1 | H44: CRITICO 10 | K44: =+[2]IDP!F44 -> 1 | N44: 0.5 | O44: 0.4
...

Sheet Guia de Evidencias 2,0
A1: Area de Interes | B1: Atributo | C1: BPL | D1: Critico | E1: Declaración de Buena Practica | F1: Comentarios sobre evidencias | G1: # | H1: Componente
A2: IFT | B2: EMPLAZAMIENTO | C2: ENTORNO Y SEGURIDAD EXTERNA | E2: La localización geográfica donde se emplaza el depósito es segura en cuanto riesgos de seguridad patrimonial | F2: Inspección visual o entrevista al distribuidor o empleados | G2: 1.1.1 | H2: Predios cerrados, o Zonas industriales o logísticas | I2: =COUNTA(G2:G188) -> 187
G3: 1.1.2 | H3: Zona segura, con vigilancia de fuerzas públicas o privadas
G4: 1.1.3 | H4: Zona provista de iluminación pública o propia.
G5: 1.1.4 | H5: Existen cámaras de video externas pública o propia que cubran el ingreso principal o aledaños
A6: IFT | B6: EMPLAZAMIENTO | C6: ENTORNO - ACCESO | D6: X | E6: La localización geográfica donde se emplaza el depósito permite / autoriza acceso a vehículos, inclusive de gran porte | F6: Verificar ingreso o medir dimensiones del acceso y consultar restricciones municipales, constrastar con info de CRM | G6: 1.2.1 | H6: Capacidad de recibir unidades de alto tonelaje
A7: IFT | B7: EMPLAZAMIENTO | C7: PREDIO Y CIRCULACION | E7: Los accesos / calles internas del predio - o del entorno del depósito o vía pública - permiten la circulación segura de vehículos y otro equipamiento de maniobra | F7: Inspección visual y entrevista al distribuidor o empleados, validar que los vehiculos al momento de la carga/decarga no obstaculicen el trafico | G7: 1.3.2 | H7: Entorno sin problemas de congestionamiento de tráfico
G8: 1.3.3 | H8: Poseen alero o permiten el ingreso de la culata de los vehiculos para la carga/descarga en condiciones climáticas desfavorables
G9: 1.3.4 | H9: Fácil maniobrabilidad
G10: 1.3.5 | H10: Calles y accesos en buen estado, sin pendientes, consolidados o asfaltados
A11: IFT | B11: EDIFICACIÓN | C11: SEGURIDAD INTERNA | E11: La seguridad patrimonial se garantiza mediante infraestructura electrónica y/o actividades de vigilancia | F11: Inspección visual | G11: 2.1.1 | H11: Sistema de Alarmas en depósito y oficinas
G12: 2.1.2 | H12: Cámaras de Video en distintos sectores, con grabación y registro
A13: IFT | B13: EDIFICACIÓN | C13: LAY OUT - CAPACIDAD Y MODULACION | D13: X | E13: La capacidad del depósito es adecuada para el volumen de ventas , asegura el flujo físico continuo y permite mantener la cobertura de stock definida por Arcor. | F13: Analisis de stock vs capacidad. Documentos y entrevista con personal | G13: 2.2.1 | H13: Días hábiles promedio 6 meses de venta almacenados en la bodega (MinImo 21 dias)
A14: IFT | B14: EDIFICACIÓN | C14: TECHOS y PAREDES: ESTADO | E14: Las paredes y los techos del depósito se encuentran en buen estado y cuentan con elementos que garantizan las condiciones de conservación de los productos , definidos por Arcor. Temperatura 35°C (máxima promedio). | F14: Inspección Visual | G14: 2.3.1 | H14: Techo aislado y/o revestido, bien conservado
F15: Respecto de las paredes se validará que todas las paredes de la Distribuidora se encuentra revocadas o revestidas con material liso que no permita la acumulación de tierra o plagas | G15: 2.3.2 | H15: Paredes aisladas y/o revestidas, bien conservadas, que no permitan la acumulación de tierra o plagas
F16: Sino cuenta con extractores eolicos, pero se comprueba una temperatura adecuada en base a registros el componente se cumple. | G16: 2.3.3 | H16: Cuenta con extractores eólicos y/o ventilación forzada
F17: Inspección Visual. Verificar que no sean de mercurio | G17: 2.3.4 | H17: Posee termómetro en sector Secos, (no se permiten termometros de mercurio)
A18: IFT | B18: EDIFICACIÓN | C18: PISOS y JUNTAS: ESTADO | E18: Los pisos y juntas interiores del depósito son adecuados, en buen estado, garantizando y asegurando la operación. | F18: Inspección visual | G18: 2.4.1 | H18: Posee terminación alisada (a llana)
G19: 2.4.2 | H19: Las juntas poseen relleno (compuesto elástico ) y/o protección metálica que no genere golpes al transito de apiladoras o transpaletas
G20: 2.4.3 | H20: No posee desniveles entre los paños
G21: 2.4.4 | H21: El piso no desprende polvillo y/o no se visualizan grietas
A22: IFT | B22: EDIFICACIÓN | C22: ABERTURAS | E22: El depósito cuenta con al menos 2 portones e ingreso peatonal independiente | F22: Inspección visual | G22: 2.5.1 | H22: Cuenta con 2 o más portones
G23: 2.5.2 | H23: Posee ingreso de personal independiente de la carga
A24: IFT | B24: EDIFICACIÓN | C24: ILUMNACIÓN | E24: El depósito cuenta con lluminación adecuada para garantizar una operación logística eficaz y segura | F24: Inspección visual | G24: 2.6.1 | H24: Se encuentran por encima del nivel más alto de almacenamiento
G25: 2.6.2 | H25: Se encuentran centradas a lo largo de los pasillos
G26: 2.6.3 | H26: No se perciben sectores oscuros que afecten la operación
G27: 2.6.4 | H27: Se aprovecha la luz natural para la operación diurna sin aumento considerable de la temperatura en el interior
A28: IFT | B28: EDIFICACIÓN | C28: DESAGÛES | E28: El depósito cuenta con desagües que permiten evacuar el agua acumulada por lluvia | F28: Inspección visual y entrevista al distribuidor o empleados | G28: 2.7.1 | H28: Se ubican en el exterior del edificio
G29: 2.7.2 | H29: Se encuentran en buen estado (no se visualizan manchas de humedad), con rejillas de protección
A30: IFT | B30: ALMACENAMIENTO Y MANIPULEO | C30: EPPS y Extinguidores | D30: X | E30: Uso correcto de EPP (zapatos, cascos) y extintores en correctas condiciones | F30: Visual: verificar que se usen según reglamentación o evaluación de riesgos. Verificar si cuentan con stock para visitas. Ver area de guardado | G30: 3.1.1 | H30: Uso correcto de EPPS (zapatos o casco según reglamentación local vigente)
F31: Visual: verificar la ubicación de los extintores y su fecha de vencimiento | G31: 3.1.2 | H31: Extintores bien ubicados y en período de vencimiento
A32: IFT | B32: ALMACENAMIENTO Y MANIPULEO | C32: POP Y MOBILIARIO | E32: La infraestructura del depósito permite el almacenamiento de material promocional y de conservación en punto de venta (POP, mobiliario, freezers, etc) en un lugar aislado de la mercadería y seguro para la conservación y rotación de los mismos. | F32: Inspección visual y solicitar inventario en sistema o planilla | G32: 3.2.1 | H32: Los freezers y/o mobiliarios usados se encuentran en condiciones de higiene adecuadas
G33: 3.2.2 | H33: El material se encuentra inventariado el mueble pesado
G34: 3.2.3 | H34: El material se encuentra en un sector aislado de la mercadería
G35: 3.2.4 | H35: El material se encuentra identificado
A36: IFT | B36: ALMACENAMIENTO Y MANIPULEO | C36: CAMARA DE REFRIGERADOS | E36: La cámara de refrigerados cuenta con las condiciones necesarias para cubir las necesidades de almacenamiento y control de temperatura (entre 15°C a 25 °C) garantizando la conservación de la mercadería. | F36: Inspección visual, de registros, y análisis contra picos de temporada de mercadería que requiere cámara. Respecto de las paredes se validará que todas las paredes de la camara se encuentra con aislación termica. Los únicos termómetros que no se permiten tener colocados son los que contienen mercurio | G36: 3.3.1 | H36: Indice nivel de capacidad para productos refrigerados es menor que 1 respecto a su capacidad teorica real
G37: 3.3.2 | H37: Posee aislación térmica en paredes laterales, techo y acceso. Paredes aisladas y/o revestidas, bien conservadas, que no permitan la acumulación de tierra o plagas
G38: 3.3.3 | H38: Posee termómetro en Cámara de Refrigerados, (no se permiten termometros de mercurio)
A39: IFT | B39: ALMACENAMIENTO Y MANIPULEO | C39: CAMARA DE CONGELADOS | E39: La cámara de congelados cuenta con las condiciones necesarias para cubir las necesidades de almacenamiento y control de temperatura (-18 °C) garantizando la conservación de la mercadería. | F39: Inspección visual, de registros, y análisis contra picos de temporada de mercadería que requiere cámara.Verificar que la ubicación de la cámara a la zona de descarga no supere los 15min haciendo el recorrido caminando.Verifcar cuantos pallets recibe | G39: 3.3.1 | H39: Indice nivel de capacidad para productos congelados es menor que 1 respecto a su capacidad teorica real
G40: 3.3.2 | H40: Su ubicación permite carga / descarga directa desde el transporte
...

Sheet Plan de Acción
C3: PLAN DE ACCION - AUDITORIA RED ACTIVA 2.0
F4: PROGRESO | J4: FECHA DE REVISION
F5: VACIO | J5: 45302
F6: COMPLETO | G6: =+COUNTIF($I$12:$I$33,F6) -> 0 | H6: =IFERROR(G6/$G$9,0) -> 0
F7: EN CURSO | G7: =+COUNTIF($I$12:$I$33,F7) -> 0 | H7: =IFERROR(G7/$G$9,0) -> 0
F8: DEMORADO | G8: =+COUNTIF($I$12:$I$33,F8) -> 0 | H8: =IFERROR(G8/$G$9,0) -> 0
F9: TOTAL | G9: =+SUM(G6:G8) -> 0 | H9: =IFERROR(G9/$G$9,0) -> 0
B11: Atributo | C11: Buena Práctica Logística | D11: Componente | E11: Accion | F11: Responsable | G11: Fecha Inicio | H11: Fecha Fin | I11: Status | J11: Observaciones
I12: VACIO
I13: VACIO
I14: VACIO
I15: VACIO
I16: VACIO
I17: VACIO
I18: VACIO
I19: VACIO
I20: VACIO
I21: VACIO
I22: VACIO
I23: VACIO
... I33: VACIO

Sheet 5.0>>>

Sheet Dashboard Gral
B5: SEGURIDAD | D5: =+'Resumen - Se oculta 5,0'!I6 -> 0.35294118 | F5: =+'Resumen - Se oculta 5,0'!I5 -> 0.30436169
B6: CALIDAD | D6: =+'Resumen - Se oculta 5,0'!I18 -> 0.78378378
B7: INFRAESTRUCTURA LAYOUT Y FLOTA | D7: =+'Resumen - Se oculta 5,0'!I23 -> 0.66666667
B8: ORGANIZACIÓN Y CULTURA | D8: =+'Resumen - Se oculta 5,0'!I44 -> 0.28
B9: 5S | D9: =+'Resumen - Se oculta 5,0'!I54 -> 0.75
B10: PROCESOS LOGISTICOS | D10: =+'Resumen - Se oculta 5,0'!I58 -> 0.96153846 | F10: =+'Resumen - Se oculta 5,0'!I57 -> 0.2267094
B11: ESTANDARIZACION | D11: =+'Resumen - Se oculta 5,0'!I72 -> 0.91666667
B12: RUTINA E INDICADORES | D12: =+'Resumen - Se oculta 5,0'!I80 -> 0.44444444
B13: NIVEL DE SERVICIO Y TECNOLOGIA | D13: =+'Resumen - Se oculta 5,0'!I88 -> 0.22222222
B14: GESTION DE PROVEEDORES | D14: =+'Resumen - Se oculta 5,0'!I95 -> 0
B15: RELACIONES Y DESARROLLO DE LA COMUNIDAD | D15: =+'Resumen - Se oculta 5,0'!I98 -> 0
B16: GESTION AMBIENTAL | D16: =+'Resumen - Se oculta 5,0'!I101 -> 0 | J16: =Condicionales!$Q$6 -> Condición 1: No OK
B17: PLANEAMIENTO ESTRATEGICO | D17: =+'Resumen - Se oculta 5,0'!I105 -> 0.5 | F17: =+'Resumen - Se oculta 5,0'!I104 -> 0.045 | J17: =+Condicionales!$Q$10 -> Condición 2: OK
B18: GERENCIAMIENTO Y MEJORA CONTINUA | D18: =+'Resumen - Se oculta 5,0'!I108 -> 0.4 | J18: =+Condicionales!$Q$14 -> Condición 3: No Aplica
B22: 85 % >= Proactivo <= 100 %
B23: 70 % >= Activo < 85 %
B24: 50 % >= Reactivo < 70 %
B25: 25 % >= Inactivo < 50 %
B26: 0 % >= No Aplica < 25 %

Sheet Operacional
AO1: 0
F2: EV25 | G2: =+F4+Estandarización!F4+Mejora!F4 -> 0.57607109 | K2: AE 25 | M2: =+M6 -> EV24 | AO2: 1
E3: Nivel | F3: =+F8*$AB$8+F64*$AB$64+F111*$AB$111+F186*$AB$186+F212*$AB$212 -> 0.60872337 | G3: =+"Resultado acumulado "&" "&ROUND(G2*100,1)&"%" -> Resultado acumulado 57,6% | K3: =+K8*$AB$8+K64*$AB$64+K111*$AB$111+K186*$AB$186+K212*$AB$212 -> 0 | M3: =+M8*AB8+M64*AB64+M111*AB111+M186*AB186+M212*AB212 -> 0 | AA3: Nivel | AB3: =+AA8+AA64+AA111+AA186+AA212 -> 0.5 | AO3: N/A
E4: Programa | F4: =+F8*$AA$8+F64*$AA$64+F111*$AA$111+F186*$AA$186+F212*$AA$212 -> 0.30436169 | K4: =+K8*$AA$8+K64*$AA$64+K111*$AA$111+K186*$AA$186+K212*$AA$212 -> 0 | M4: =+M8*AA8+M64*AA64+M111*AA111+M186*AA186+M212*AA212 -> 0 | AO4: NA - 1
B5: Nivel OPERACIONAL | I5: =90000/13 -> 6923.0769 | AA5: Ponderaciones 2025 | AO5: NA - 0
B6: NRO. | C6: Buena Practica Logistica | E6: Componente | F6: EV25 | G6: Foco | H6: Zoom | I6: Comentarios Evaluación | K6: AE 25 | M6: EV24 | N6: Comentarios Evaluación 2024 | AA6: Comp
B8: 1 | C8: SEGURIDAD | F8: =IFERROR(SUMIF(F9:F63,1,F9:F63)/SUM(COUNTIF(F9:F63,1),COUNTIF(F9:F63,0)),0) -> 0.35294118 | K8: =IFERROR(SUMIF(K9:K63,1,K9:K63)/SUM(COUNTIF(K9:K63,1),COUNTIF(K9:K63,0)),0) -> 0 | M8: =IFERROR(SUMIF(M9:M63,1,M9:M63)/SUM(COUNTIF(M9:M63,1),COUNTIF(M9:M63,0)),0) -> 0 | AA8: 0.1 | AB8: =+AA8/$AB$3 -> 0.2
